[2024-09-23T02:00:13.792+0000] {taskinstance.py:1159} INFO - Dependencies all met for dep_context=non-requeueable deps ti=<TaskInstance: raw_ingestion_15min.trigger_stage_processing scheduled__2024-09-23T01:45:00+00:00 [queued]>
[2024-09-23T02:00:13.801+0000] {taskinstance.py:1159} INFO - Dependencies all met for dep_context=requeueable deps ti=<TaskInstance: raw_ingestion_15min.trigger_stage_processing scheduled__2024-09-23T01:45:00+00:00 [queued]>
[2024-09-23T02:00:13.802+0000] {taskinstance.py:1361} INFO - Starting attempt 1 of 0
[2024-09-23T02:00:13.813+0000] {taskinstance.py:1382} INFO - Executing <Task(TriggerDagRunOperator): trigger_stage_processing> on 2024-09-23 01:45:00+00:00
[2024-09-23T02:00:13.817+0000] {standard_task_runner.py:57} INFO - Started process 4274 to run task
[2024-09-23T02:00:13.819+0000] {standard_task_runner.py:84} INFO - Running: ['airflow', 'tasks', 'run', 'raw_ingestion_15min', 'trigger_stage_processing', 'scheduled__2024-09-23T01:45:00+00:00', '--job-id', '467', '--raw', '--subdir', 'DAGS_FOLDER/raw_ingestion_15min.py', '--cfg-path', '/tmp/tmp5snn8tfm']
[2024-09-23T02:00:13.820+0000] {standard_task_runner.py:85} INFO - Job 467: Subtask trigger_stage_processing
[2024-09-23T02:00:13.917+0000] {task_command.py:416} INFO - Running <TaskInstance: raw_ingestion_15min.trigger_stage_processing scheduled__2024-09-23T01:45:00+00:00 [running]> on host airflow-worker
[2024-09-23T02:00:14.066+0000] {taskinstance.py:1662} INFO - Exporting env vars: AIRFLOW_CTX_DAG_OWNER='***' AIRFLOW_CTX_DAG_ID='raw_ingestion_15min' AIRFLOW_CTX_TASK_ID='trigger_stage_processing' AIRFLOW_CTX_EXECUTION_DATE='2024-09-23T01:45:00+00:00' AIRFLOW_CTX_TRY_NUMBER='1' AIRFLOW_CTX_DAG_RUN_ID='scheduled__2024-09-23T01:45:00+00:00'
[2024-09-23T02:00:14.167+0000] {taskinstance.py:1937} ERROR - Task failed with exception
Traceback (most recent call last):
  File "/home/airflow/.local/lib/python3.8/site-packages/airflow/operators/trigger_dagrun.py", line 186, in execute
    raise e
  File "/home/airflow/.local/lib/python3.8/site-packages/airflow/operators/trigger_dagrun.py", line 163, in execute
    dag_run = trigger_dag(
  File "/home/airflow/.local/lib/python3.8/site-packages/airflow/api/common/trigger_dag.py", line 122, in trigger_dag
    triggers = _trigger_dag(
  File "/home/airflow/.local/lib/python3.8/site-packages/airflow/api/common/trigger_dag.py", line 78, in _trigger_dag
    raise DagRunAlreadyExists(dag_run=dag_run, execution_date=execution_date, run_id=run_id)
airflow.exceptions.DagRunAlreadyExists: A DAG Run already exists for DAG stage_processing at 2024-09-23T00:00:00+00:00 with run id manual__2024-09-23T00:00:00+00:00
[2024-09-23T02:00:14.169+0000] {taskinstance.py:1400} INFO - Marking task as FAILED. dag_id=raw_ingestion_15min, task_id=trigger_stage_processing, execution_date=20240923T014500, start_date=20240923T020013, end_date=20240923T020014
[2024-09-23T02:00:14.185+0000] {standard_task_runner.py:104} ERROR - Failed to execute job 467 for task trigger_stage_processing (A DAG Run already exists for DAG stage_processing at 2024-09-23T00:00:00+00:00 with run id manual__2024-09-23T00:00:00+00:00; 4274)
[2024-09-23T02:00:14.232+0000] {local_task_job_runner.py:228} INFO - Task exited with return code 1
[2024-09-23T02:00:14.268+0000] {taskinstance.py:2778} INFO - 0 downstream tasks scheduled from follow-on schedule check
