[2024-09-21T20:32:00.193+0000] {taskinstance.py:1159} INFO - Dependencies all met for dep_context=non-requeueable deps ti=<TaskInstance: raw_ingestion.spark_raw_ingestion_empresa scheduled__2024-09-21T20:00:00+00:00 [queued]>
[2024-09-21T20:32:00.207+0000] {taskinstance.py:1159} INFO - Dependencies all met for dep_context=requeueable deps ti=<TaskInstance: raw_ingestion.spark_raw_ingestion_empresa scheduled__2024-09-21T20:00:00+00:00 [queued]>
[2024-09-21T20:32:00.207+0000] {taskinstance.py:1361} INFO - Starting attempt 1 of 0
[2024-09-21T20:32:00.232+0000] {taskinstance.py:1382} INFO - Executing <Task(SSHOperator): spark_raw_ingestion_empresa> on 2024-09-21 20:00:00+00:00
[2024-09-21T20:32:00.237+0000] {standard_task_runner.py:57} INFO - Started process 64 to run task
[2024-09-21T20:32:00.240+0000] {standard_task_runner.py:84} INFO - Running: ['airflow', 'tasks', 'run', 'raw_ingestion', 'spark_raw_ingestion_empresa', 'scheduled__2024-09-21T20:00:00+00:00', '--job-id', '343', '--raw', '--subdir', 'DAGS_FOLDER/raw_ingestion.py', '--cfg-path', '/tmp/tmppjw0_7mt']
[2024-09-21T20:32:00.242+0000] {standard_task_runner.py:85} INFO - Job 343: Subtask spark_raw_ingestion_empresa
[2024-09-21T20:32:00.415+0000] {task_command.py:416} INFO - Running <TaskInstance: raw_ingestion.spark_raw_ingestion_empresa scheduled__2024-09-21T20:00:00+00:00 [running]> on host airflow-worker
[2024-09-21T20:32:00.810+0000] {taskinstance.py:1662} INFO - Exporting env vars: AIRFLOW_CTX_DAG_OWNER='***' AIRFLOW_CTX_DAG_ID='raw_ingestion' AIRFLOW_CTX_TASK_ID='spark_raw_ingestion_empresa' AIRFLOW_CTX_EXECUTION_DATE='2024-09-21T20:00:00+00:00' AIRFLOW_CTX_TRY_NUMBER='1' AIRFLOW_CTX_DAG_RUN_ID='scheduled__2024-09-21T20:00:00+00:00'
[2024-09-21T20:32:00.811+0000] {ssh.py:141} INFO - Creating ssh_client
[2024-09-21T20:32:00.812+0000] {ssh.py:114} INFO - ssh_hook is not provided or invalid. Trying ssh_conn_id to create SSHHook.
[2024-09-21T20:32:00.862+0000] {base.py:73} INFO - Using connection ID 'spark_ssh_default' for task execution.
[2024-09-21T20:32:00.864+0000] {ssh.py:300} WARNING - No Host Key Verification. This won't protect against Man-In-The-Middle attacks
[2024-09-21T20:32:00.876+0000] {transport.py:1893} INFO - Connected (version 2.0, client OpenSSH_8.9p1)
[2024-09-21T20:32:03.270+0000] {transport.py:1893} INFO - Authentication (password) failed.
[2024-09-21T20:32:03.271+0000] {ssh.py:342} INFO - Failed to connect. Sleeping before retry attempt 1
[2024-09-21T20:32:06.610+0000] {transport.py:1893} INFO - Connected (version 2.0, client OpenSSH_8.9p1)
[2024-09-21T20:32:09.000+0000] {transport.py:1893} INFO - Authentication (password) failed.
[2024-09-21T20:32:09.000+0000] {ssh.py:342} INFO - Failed to connect. Sleeping before retry attempt 2
[2024-09-21T20:32:13.372+0000] {transport.py:1893} INFO - Connected (version 2.0, client OpenSSH_8.9p1)
[2024-09-21T20:32:15.770+0000] {transport.py:1893} INFO - Authentication (password) failed.
[2024-09-21T20:32:15.771+0000] {taskinstance.py:1937} ERROR - Task failed with exception
Traceback (most recent call last):
  File "/home/airflow/.local/lib/python3.8/site-packages/airflow/providers/ssh/operators/ssh.py", line 177, in execute
    with self.get_ssh_client() as ssh_client:
  File "/home/airflow/.local/lib/python3.8/site-packages/airflow/providers/ssh/operators/ssh.py", line 142, in get_ssh_client
    return self.hook.get_conn()
  File "/home/airflow/.local/lib/python3.8/site-packages/airflow/providers/ssh/hooks/ssh.py", line 346, in get_conn
    for attempt in Retrying(
  File "/home/airflow/.local/lib/python3.8/site-packages/tenacity/__init__.py", line 347, in __iter__
    do = self.iter(retry_state=retry_state)
  File "/home/airflow/.local/lib/python3.8/site-packages/tenacity/__init__.py", line 325, in iter
    raise retry_exc.reraise()
  File "/home/airflow/.local/lib/python3.8/site-packages/tenacity/__init__.py", line 158, in reraise
    raise self.last_attempt.result()
  File "/usr/local/lib/python3.8/concurrent/futures/_base.py", line 437, in result
    return self.__get_result()
  File "/usr/local/lib/python3.8/concurrent/futures/_base.py", line 389, in __get_result
    raise self._exception
  File "/home/airflow/.local/lib/python3.8/site-packages/airflow/providers/ssh/hooks/ssh.py", line 353, in get_conn
    client.connect(**connect_kwargs)
  File "/home/airflow/.local/lib/python3.8/site-packages/paramiko/client.py", line 485, in connect
    self._auth(
  File "/home/airflow/.local/lib/python3.8/site-packages/paramiko/client.py", line 818, in _auth
    raise saved_exception
  File "/home/airflow/.local/lib/python3.8/site-packages/paramiko/client.py", line 805, in _auth
    self._transport.auth_password(username, password)
  File "/home/airflow/.local/lib/python3.8/site-packages/paramiko/transport.py", line 1587, in auth_password
    return self.auth_handler.wait_for_response(my_event)
  File "/home/airflow/.local/lib/python3.8/site-packages/paramiko/auth_handler.py", line 263, in wait_for_response
    raise e
paramiko.ssh_exception.AuthenticationException: Authentication failed.
[2024-09-21T20:32:15.802+0000] {taskinstance.py:1400} INFO - Marking task as FAILED. dag_id=raw_ingestion, task_id=spark_raw_ingestion_empresa, execution_date=20240921T200000, start_date=20240921T203200, end_date=20240921T203215
[2024-09-21T20:32:15.821+0000] {standard_task_runner.py:104} ERROR - Failed to execute job 343 for task spark_raw_ingestion_empresa (Authentication failed.; 64)
[2024-09-21T20:32:15.832+0000] {local_task_job_runner.py:228} INFO - Task exited with return code 1
[2024-09-21T20:32:15.869+0000] {taskinstance.py:2778} INFO - 0 downstream tasks scheduled from follow-on schedule check
