[2024-09-15T20:27:44.604+0000] {taskinstance.py:1159} INFO - Dependencies all met for dep_context=non-requeueable deps ti=<TaskInstance: raw_ingestion.raw_ingestion manual__2024-09-15T20:27:42.693756+00:00 [queued]>
[2024-09-15T20:27:44.630+0000] {taskinstance.py:1159} INFO - Dependencies all met for dep_context=requeueable deps ti=<TaskInstance: raw_ingestion.raw_ingestion manual__2024-09-15T20:27:42.693756+00:00 [queued]>
[2024-09-15T20:27:44.631+0000] {taskinstance.py:1361} INFO - Starting attempt 1 of 11
[2024-09-15T20:27:44.656+0000] {taskinstance.py:1382} INFO - Executing <Task(SSHOperator): raw_ingestion> on 2024-09-15 20:27:42.693756+00:00
[2024-09-15T20:27:44.665+0000] {standard_task_runner.py:57} INFO - Started process 88 to run task
[2024-09-15T20:27:44.668+0000] {standard_task_runner.py:84} INFO - Running: ['airflow', 'tasks', 'run', 'raw_ingestion', 'raw_ingestion', 'manual__2024-09-15T20:27:42.693756+00:00', '--job-id', '46', '--raw', '--subdir', 'DAGS_FOLDER/raw_ingestion.py', '--cfg-path', '/tmp/tmp1a7vsven']
[2024-09-15T20:27:44.669+0000] {standard_task_runner.py:85} INFO - Job 46: Subtask raw_ingestion
[2024-09-15T20:27:44.853+0000] {task_command.py:416} INFO - Running <TaskInstance: raw_ingestion.raw_ingestion manual__2024-09-15T20:27:42.693756+00:00 [running]> on host airflow-worker
[2024-09-15T20:27:45.185+0000] {taskinstance.py:1662} INFO - Exporting env vars: AIRFLOW_CTX_DAG_OWNER='***' AIRFLOW_CTX_DAG_ID='raw_ingestion' AIRFLOW_CTX_TASK_ID='raw_ingestion' AIRFLOW_CTX_EXECUTION_DATE='2024-09-15T20:27:42.693756+00:00' AIRFLOW_CTX_TRY_NUMBER='1' AIRFLOW_CTX_DAG_RUN_ID='manual__2024-09-15T20:27:42.693756+00:00'
[2024-09-15T20:27:45.187+0000] {ssh.py:141} INFO - Creating ssh_client
[2024-09-15T20:27:45.188+0000] {ssh.py:114} INFO - ssh_hook is not provided or invalid. Trying ssh_conn_id to create SSHHook.
[2024-09-15T20:27:45.238+0000] {base.py:73} INFO - Using connection ID 'spark_ssh_default' for task execution.
[2024-09-15T20:27:45.240+0000] {ssh.py:300} WARNING - No Host Key Verification. This won't protect against Man-In-The-Middle attacks
[2024-09-15T20:27:45.256+0000] {transport.py:1893} INFO - Connected (version 2.0, client OpenSSH_8.9p1)
[2024-09-15T20:27:49.177+0000] {transport.py:1893} INFO - Authentication (password) failed.
[2024-09-15T20:27:49.180+0000] {ssh.py:342} INFO - Failed to connect. Sleeping before retry attempt 1
[2024-09-15T20:27:53.910+0000] {transport.py:1893} INFO - Connected (version 2.0, client OpenSSH_8.9p1)
[2024-09-15T20:27:57.817+0000] {transport.py:1893} INFO - Authentication (password) failed.
[2024-09-15T20:27:57.817+0000] {ssh.py:342} INFO - Failed to connect. Sleeping before retry attempt 2
[2024-09-15T20:28:02.464+0000] {transport.py:1893} INFO - Connected (version 2.0, client OpenSSH_8.9p1)
[2024-09-15T20:28:04.451+0000] {transport.py:1893} INFO - Authentication (password) failed.
[2024-09-15T20:28:04.452+0000] {taskinstance.py:1937} ERROR - Task failed with exception
Traceback (most recent call last):
  File "/home/airflow/.local/lib/python3.8/site-packages/airflow/providers/ssh/operators/ssh.py", line 177, in execute
    with self.get_ssh_client() as ssh_client:
  File "/home/airflow/.local/lib/python3.8/site-packages/airflow/providers/ssh/operators/ssh.py", line 142, in get_ssh_client
    return self.hook.get_conn()
  File "/home/airflow/.local/lib/python3.8/site-packages/airflow/providers/ssh/hooks/ssh.py", line 346, in get_conn
    for attempt in Retrying(
  File "/home/airflow/.local/lib/python3.8/site-packages/tenacity/__init__.py", line 347, in __iter__
    do = self.iter(retry_state=retry_state)
  File "/home/airflow/.local/lib/python3.8/site-packages/tenacity/__init__.py", line 325, in iter
    raise retry_exc.reraise()
  File "/home/airflow/.local/lib/python3.8/site-packages/tenacity/__init__.py", line 158, in reraise
    raise self.last_attempt.result()
  File "/usr/local/lib/python3.8/concurrent/futures/_base.py", line 437, in result
    return self.__get_result()
  File "/usr/local/lib/python3.8/concurrent/futures/_base.py", line 389, in __get_result
    raise self._exception
  File "/home/airflow/.local/lib/python3.8/site-packages/airflow/providers/ssh/hooks/ssh.py", line 353, in get_conn
    client.connect(**connect_kwargs)
  File "/home/airflow/.local/lib/python3.8/site-packages/paramiko/client.py", line 485, in connect
    self._auth(
  File "/home/airflow/.local/lib/python3.8/site-packages/paramiko/client.py", line 818, in _auth
    raise saved_exception
  File "/home/airflow/.local/lib/python3.8/site-packages/paramiko/client.py", line 805, in _auth
    self._transport.auth_password(username, password)
  File "/home/airflow/.local/lib/python3.8/site-packages/paramiko/transport.py", line 1587, in auth_password
    return self.auth_handler.wait_for_response(my_event)
  File "/home/airflow/.local/lib/python3.8/site-packages/paramiko/auth_handler.py", line 263, in wait_for_response
    raise e
paramiko.ssh_exception.AuthenticationException: Authentication failed.
[2024-09-15T20:28:04.489+0000] {taskinstance.py:1400} INFO - Marking task as UP_FOR_RETRY. dag_id=raw_ingestion, task_id=raw_ingestion, execution_date=20240915T202742, start_date=20240915T202744, end_date=20240915T202804
[2024-09-15T20:28:04.510+0000] {standard_task_runner.py:104} ERROR - Failed to execute job 46 for task raw_ingestion (Authentication failed.; 88)
[2024-09-15T20:28:04.537+0000] {local_task_job_runner.py:228} INFO - Task exited with return code 1
[2024-09-15T20:28:04.583+0000] {taskinstance.py:2778} INFO - 0 downstream tasks scheduled from follow-on schedule check
