[2024-09-12T23:04:38.019+0000] {taskinstance.py:1159} INFO - Dependencies all met for dep_context=non-requeueable deps ti=<TaskInstance: raw_ingestion.raw_ingestion manual__2024-09-12T23:04:37.323078+00:00 [queued]>
[2024-09-12T23:04:38.027+0000] {taskinstance.py:1159} INFO - Dependencies all met for dep_context=requeueable deps ti=<TaskInstance: raw_ingestion.raw_ingestion manual__2024-09-12T23:04:37.323078+00:00 [queued]>
[2024-09-12T23:04:38.027+0000] {taskinstance.py:1361} INFO - Starting attempt 1 of 11
[2024-09-12T23:04:38.040+0000] {taskinstance.py:1382} INFO - Executing <Task(SSHOperator): raw_ingestion> on 2024-09-12 23:04:37.323078+00:00
[2024-09-12T23:04:38.047+0000] {standard_task_runner.py:57} INFO - Started process 339 to run task
[2024-09-12T23:04:38.049+0000] {standard_task_runner.py:84} INFO - Running: ['airflow', 'tasks', 'run', 'raw_ingestion', 'raw_ingestion', 'manual__2024-09-12T23:04:37.323078+00:00', '--job-id', '32', '--raw', '--subdir', 'DAGS_FOLDER/raw_ingestion.py', '--cfg-path', '/tmp/tmpcctkyiiv']
[2024-09-12T23:04:38.049+0000] {standard_task_runner.py:85} INFO - Job 32: Subtask raw_ingestion
[2024-09-12T23:04:38.140+0000] {task_command.py:416} INFO - Running <TaskInstance: raw_ingestion.raw_ingestion manual__2024-09-12T23:04:37.323078+00:00 [running]> on host airflow-worker
[2024-09-12T23:04:38.288+0000] {taskinstance.py:1662} INFO - Exporting env vars: AIRFLOW_CTX_DAG_OWNER='***' AIRFLOW_CTX_DAG_ID='raw_ingestion' AIRFLOW_CTX_TASK_ID='raw_ingestion' AIRFLOW_CTX_EXECUTION_DATE='2024-09-12T23:04:37.323078+00:00' AIRFLOW_CTX_TRY_NUMBER='1' AIRFLOW_CTX_DAG_RUN_ID='manual__2024-09-12T23:04:37.323078+00:00'
[2024-09-12T23:04:38.289+0000] {ssh.py:141} INFO - Creating ssh_client
[2024-09-12T23:04:38.289+0000] {ssh.py:114} INFO - ssh_hook is not provided or invalid. Trying ssh_conn_id to create SSHHook.
[2024-09-12T23:04:38.314+0000] {base.py:73} INFO - Using connection ID 'spark_ssh_default' for task execution.
[2024-09-12T23:04:38.314+0000] {ssh.py:300} WARNING - No Host Key Verification. This won't protect against Man-In-The-Middle attacks
[2024-09-12T23:04:46.318+0000] {ssh.py:342} INFO - Failed to connect. Sleeping before retry attempt 1
[2024-09-12T23:04:58.921+0000] {ssh.py:342} INFO - Failed to connect. Sleeping before retry attempt 2
[2024-09-12T23:05:11.659+0000] {taskinstance.py:1937} ERROR - Task failed with exception
Traceback (most recent call last):
  File "/home/airflow/.local/lib/python3.8/site-packages/airflow/providers/ssh/operators/ssh.py", line 177, in execute
    with self.get_ssh_client() as ssh_client:
  File "/home/airflow/.local/lib/python3.8/site-packages/airflow/providers/ssh/operators/ssh.py", line 142, in get_ssh_client
    return self.hook.get_conn()
  File "/home/airflow/.local/lib/python3.8/site-packages/airflow/providers/ssh/hooks/ssh.py", line 346, in get_conn
    for attempt in Retrying(
  File "/home/airflow/.local/lib/python3.8/site-packages/tenacity/__init__.py", line 347, in __iter__
    do = self.iter(retry_state=retry_state)
  File "/home/airflow/.local/lib/python3.8/site-packages/tenacity/__init__.py", line 325, in iter
    raise retry_exc.reraise()
  File "/home/airflow/.local/lib/python3.8/site-packages/tenacity/__init__.py", line 158, in reraise
    raise self.last_attempt.result()
  File "/usr/local/lib/python3.8/concurrent/futures/_base.py", line 437, in result
    return self.__get_result()
  File "/usr/local/lib/python3.8/concurrent/futures/_base.py", line 389, in __get_result
    raise self._exception
  File "/home/airflow/.local/lib/python3.8/site-packages/airflow/providers/ssh/hooks/ssh.py", line 353, in get_conn
    client.connect(**connect_kwargs)
  File "/home/airflow/.local/lib/python3.8/site-packages/paramiko/client.py", line 377, in connect
    to_try = list(self._families_and_addresses(hostname, port))
  File "/home/airflow/.local/lib/python3.8/site-packages/paramiko/client.py", line 202, in _families_and_addresses
    addrinfos = socket.getaddrinfo(
  File "/usr/local/lib/python3.8/socket.py", line 918, in getaddrinfo
    for res in _socket.getaddrinfo(host, port, family, type, proto, flags):
socket.gaierror: [Errno -3] Temporary failure in name resolution
[2024-09-12T23:05:11.687+0000] {taskinstance.py:1400} INFO - Marking task as UP_FOR_RETRY. dag_id=raw_ingestion, task_id=raw_ingestion, execution_date=20240912T230437, start_date=20240912T230438, end_date=20240912T230511
[2024-09-12T23:05:11.704+0000] {standard_task_runner.py:104} ERROR - Failed to execute job 32 for task raw_ingestion ([Errno -3] Temporary failure in name resolution; 339)
[2024-09-12T23:05:11.742+0000] {local_task_job_runner.py:228} INFO - Task exited with return code 1
[2024-09-12T23:05:11.774+0000] {taskinstance.py:2778} INFO - 0 downstream tasks scheduled from follow-on schedule check
